Workbook

Sheet  En tramite 23-26
D1: FECHA DE HOY | F1: =TODAY() -> 46253
A3: No. REGISTRO | B3: CONSECUTIVO | C3: No. CONSTANCIA | D3: NOMBRE | E3: Nombre Minusculas | F3: MATRÍCULA | G3: TELÉFONO | H3: CORREO ESTUDIANTE | I3: GRADO-CARRERA | J3: TURNO | K3: CARRERA | L3: OBSERVACIONES | M3: PROCESO | N3: EMPRESA | O3: SECTOR | P3: NOMBRE DEL PROYECTO | Q3: TEL. EMPRESA | R3: DIRECCIÓN EMPRESA | S3: CORR. EM | T3: GENERACIÓN | U3: H/M | V3: BECADOS | W3: MONTO | X3: S. PRÁC | Y3: S. PRÁC. | Z3: F. INICIO | AA3: DIA | AB3: MES | AC3: AÑO | AD3: C.PRES. | AE3: C.PRES.2 | AF3: F.C.P | AG3: C. ACEP | AH3: C. ACEP. | AI3: F.C.A | AJ3: DIA 3 | AK3: MES4 | AL3: AÑO 5 | AM3: P. TRABJ | AN3: P. TRABJ. | AO3: F. P.TR | AP3: I. INTER | AQ3: I. INTER. | AR3: F.I.I. | AS3: F.L. I.I. | AT3: ESTADO | AU3: INF. FINAL | AV3: INF. FINAL6 | AW3: F.I.FINAL | AX3: ESTADO7 | AY3: R-E-FINAL | AZ3: R-E-FINAL8 | BA3: F.R-E FINAL | BB3: CONS.T | BC3: C.T | BD3: F.C.T | BE3: DIA2 | BF3: MES2 | BG3: AÑO2 | BH3: PROMEDIO | BI3: TIEMPO DEL PROCESO | BJ3: RESUMEN -OBSERVACIONES | BK3: CARPETA | BL3: PASO POR CONSTANCIA | BM3: P.C.
A4: 001 | B4: 001 | C4: PC06/MATUTINO/001/2026 | D4: MAGALLÓN MATA BRENDA | E4: Magallón Mata Brenda | F4: 23422070060 249 | G4: 4427078854 | H4: brendamagallon@cecyteq.edu.mx | I4: 5T0-MECA-BM | J4: VESPERTINO | K4: MECATRÓNICA | L4: CONCLUIDO | M4: EMPRESA | N4: POLYGON TALLER 3D | O4: MICROEMPRESAS | P4: x | Q4: 4427174854 | R4: AV. PIRAMIDEZ DEL CERRITO 1 | S4: polygon3dworkshop@gmail.com | T4: 23-26 | U4: MUJER | V4: 1 | W4: N/A | X4: SI | Y4: 2 | Z4: 46076 | AB4: =TEXT(' En tramite 23-26'!$Z4,"mmmm") -> febrero | AC4: =YEAR(' En tramite 23-26'!$Z4) -> 2026 | AD4: SI | AE4: 2 | AF4: 46076 | AG4: SI | AH4: 2 | AI4: 46076 | AJ4: =DAY(' En tramite 23-26'!$AI4) -> 23 | AK4: =TEXT(' En tramite 23-26'!$AI4,"mmmm") -> febrero | AL4: =YEAR(' En tramite 23-26'!$Z4) -> 2026 | AM4: SI | AN4: 2 | AO4: 46076 | AP4: SI | AQ4: 2 | AR4: 46121 | AS4: =' En tramite 23-26'!$AI4+45 -> 46121 | AT4: ENTREGADO | AU4: SI | AV4: 2 | AW4: =' En tramite 23-26'!$AS4+45 -> 46166 | AX4: ENTREGADO | AY4: SI | AZ4: 2 | BA4: 46167 | BB4: SI | BC4: 2 | BD4: 46167 | BE4: =DAY(' En tramite 23-26'!$BD4) -> 25 | BF4: =TEXT(' En tramite 23-26'!$BD4,"mmmm") -> mayo | BG4: =YEAR(' En tramite 23-26'!$BD4) -> 2026 | BH4: 1 | BI4: 3 meses y 2 días | BJ4: BLOQUE 1 | BK4: P.P.E.C-BLOQUE 1
A5: 002 | B5: 002 | C5: PC06/MATUTINO/002/2026 | D5: MARTÍNEZ IGLESIAS JORGE LUIS | E5: Martínez Iglesias Jorge Luis | F5: 23422070060496 | G5: 4421527871 | H5: jorgemartinez2@cecyteq.edu-mx | I5: 5T0-MECA-BM | J5: VESPERTINO | K5: MECATRÓNICA | L5: CONCLUIDO | M5: CERTIFICACIÓN | N5: CERTIFICACIONES SOLIDWORKS | O5: SECTOR PÚBLICO | P5: CERTIFICACIÓN | Q5: 4423622063 | R5: AV. CANDILES 317., VALLE REAL RECIDENCIAL C.P.76903 CANDILES QRO. | S5: e.armendariz@cecyteq.edu.mx | T5: 23-26 | U5: HOMBRE | V5: 1 | W5: N/A | X5: SI | Y5: 2 | Z5: 45999 | AA5: =DAY(Tabla1[F. INICIO]) -> 8 | AB5: =TEXT(' En tramite 23-26'!$Z5,"mmmm") -> diciembre | AC5: =YEAR(' En tramite 23-26'!$Z5) -> 2025 | AD5: SI | AE5: 2 | AF5: 45999 | AG5: SI | AH5: 2 | AI5: 45999 | AJ5: =DAY(' En tramite 23-26'!$AI5) -> 8 | AK5: =TEXT(' En tramite 23-26'!$AI5,"mmmm") -> diciembre | AL5: =YEAR(' En tramite 23-26'!$Z5) -> 2025 | AM5: SI | AN5: 2 | AO5: 45999 | AP5: SI | AQ5: 2 | AR5: 46044 | AS5: =' En tramite 23-26'!$AI5+45 -> 46044 | AT5: ENTREGADO | AU5: SI | AV5: 2 | AW5: 46378 | AX5: ENTREGADO | AY5: SI | AZ5: 2 | BA5: 46090 | BB5: SI | BC5: 2 | BD5: 46090 | BE5: 9 | BF5: marzo | BG5: =YEAR(' En tramite 23-26'!$BD5) -> 2026 | BH5: 1 | BI5: 3 meses 1 día | BJ5: BLOQUE 1 | BK5: P.P.E.C-BLOQUE 1
A6: 003 | B6: 003 | C6: PC06/MATUTINO/003/2026 | D6: HERNÁNDEZ CÁRDENAS JUAN MANUEL | E6: Hernández Cárdenas Juan Manuel | F6: 23422070060023 | G6: 4425536330 | H6: juanhernadez14@cecyteq.edu.cm | I6: 5T0-BIO-AM | J6: MATUTINO | K6: BIOTECNOLOGÍA | L6: CONCLUIDO | M6: PROYECTO | N6: CECYTEQ-PLANTEL 6 CORREGIDORA. | O6: SECTOR PÚBLICO | P6: PROYECTO DE ELECTRO GERMINACIÓN DE BIZNAGA, BARRIL Y ACITRÓN CON BIOCARBONO | Q6: 4421477291 | R6: AV. CANDILES 317., VALLE REAL RECIDENCIAL C.P.76903 CANDILES QRO. | S6: teresa.r@cecyteq.edu.mx | T6: 23-26 | U6: HOMBRE | V6: 1 | W6: N/A | X6: SI | Y6: 2 | Z6: 45881 | AA6: =DAY(Tabla1[F. INICIO]) -> 12 | AB6: =TEXT(' En tramite 23-26'!$Z6,"mmmm") -> agosto | AC6: =YEAR(' En tramite 23-26'!$Z6) -> 2025 | AD6: SI | AE6: 2 | AF6: 45881 | AG6: SI | AH6: 2 | AI6: 45881 | AJ6: =DAY(' En tramite 23-26'!$AI6) -> 12 | AK6: =TEXT(' En tramite 23-26'!$AI6,"mmmm") -> agosto | AL6: =YEAR(' En tramite 23-26'!$Z6) -> 2025 | AM6: SI | AN6: 2 | AO6: 45881 | AP6: SI | AQ6: 2 | AR6: 45926 | AS6: =' En tramite 23-26'!$AI6+45 -> 45926 | AT6: ENTREGADO | AU6: SI | AV6: 2 | AW6: =' En tramite 23-26'!$AS6+45 -> 45971 | AX6: ENTREGADO | AY6: SI | AZ6: 2 | BA6: 45971 | BB6: SI | BC6: 2 | BD6: 45971 | BE6: =DAY(' En tramite 23-26'!$BD6) -> 10 | BF6: =TEXT(' En tramite 23-26'!$BD6,"mmmm") -> noviembre | BG6: =YEAR(' En tramite 23-26'!$BD6) -> 2025 | BH6: 1 | BI6: 2 meses 29 días | BJ6: BLOQUE 1 | BK6: P.P.E.C-BLOQUE 1 | BL6: 46238 | BM6: 2
A7: 004 | B7: 004 | C7: PC06/MATUTINO/004/2026 | D7: CERVANTES JUÁREZ RICARDO | E7: Cervantes Juárez Ricardo | F7: 23422070060014 | G7: 4421413148 | H7: ricardocervantes14@cecyteq.edu.mx | I7: 5T0-BIO-AM | J7: MATUTINO | K7: BIOTECNOLOGÍA | L7: CONCLUIDO | M7: PROYECTO | N7: CECYTEQ-PLANTEL 6 CORREGIDORA. | O7: SECTOR PÚBLICO | P7: PROYECTO BIONERGYQ | Q7: 4421477291 | R7: AV. CANDILES 317., VALLE REAL RECIDENCIAL C.P.76903 CANDILES QRO. | S7: teresa.r@cecyteq.edu.mx | T7: 23-26 | U7: HOMBRE | V7: 1 | W7: N/A | X7: SI | Y7: 2 | Z7: 45880 | AA7: =DAY(Tabla1[F. INICIO]) -> 11 | AB7: =TEXT(' En tramite 23-26'!$Z7,"mmmm") -> agosto | AC7: =YEAR(' En tramite 23-26'!$Z7) -> 2025 | AD7: SI | AE7: 2 | AF7: 45881 | AG7: SI | AH7: 2 | AI7: 45881 | AJ7: =DAY(' En tramite 23-26'!$AI7) -> 12 | AK7: =TEXT(' En tramite 23-26'!$AI7,"mmmm") -> agosto | AL7: =YEAR(' En tramite 23-26'!$Z7) -> 2025 | AM7: SI | AN7: 2 | AO7: 46246 | AP7: SI | AQ7: 2 | AR7: 45942 | AS7: =' En tramite 23-26'!$AI7+45 -> 45926 | AT7: ENTREGADO | AU7: SI | AV7: 2 | AW7: 46078 | AX7: ENTREGADO | AY7: SI | AZ7: 2 | BA7: 46078 | BB7: SI | BC7: 2 | BD7: 46078 | BE7: =DAY(' En tramite 23-26'!$BD7) -> 25 | BF7: =TEXT(' En tramite 23-26'!$BD7,"mmmm") -> febrero | BG7: =YEAR(' En tramite 23-26'!$BD7) -> 2026 | BH7: 1 | BI7: 6 meses y 13 días | BJ7: BLOQUE 1 | BK7: P.P.E.C-BLOQUE 1
A8: 005 | B8: 005 | C8: PC06/MATUTINO/005/2026 | D8: MARTÍNEZ HERRERA AIXA GABRIELA | E8: Martínez Herrera Aixa Gabriela | F8: 23422070060353 | G8: 4428658663 | H8: aixamartinez2@cecyteq.edu.mx | I8: 5T0-LOG-AM | J8: MATUTINO | K8: LOGÍSTICA | L8: CONCLUIDO | M8: EMPRESA | N8: HIELO GOURMET KOLD | O8: PEQUEÑAS EMPRESAS | P8: x | Q8: 4422852269 | R8: AV. CUAUHTÉMOC 4, SANTA BARBARA, EL PUEBLITO | S8: administracion@kold.mx | T8: 23-26 | U8: MUJER | V8: 1 | W8: N/A | X8: SI | Y8: 2 | Z8: 45904 | AA8: =DAY(Tabla1[F. INICIO]) -> 4 | AB8: =TEXT(' En tramite 23-26'!$Z8,"mmmm") -> septiembre | AC8: =YEAR(' En tramite 23-26'!$Z8) -> 2025 | AD8: SI | AE8: 2 | AF8: 45904 | AG8: SI | AH8: 2 | AI8: 45904 | AJ8: =DAY(' En tramite 23-26'!$AI8) -> 4 | AK8: =TEXT(' En tramite 23-26'!$AI8,"mmmm") -> septiembre | AL8: =YEAR(' En tramite 23-26'!$Z8) -> 2025 | AM8: SI | AN8: 1 | AO8: 45904 | AP8: SI | AQ8: 1 | AR8: 45947 | AS8: =' En tramite 23-26'!$AI8+45 -> 45949 | AT8: ENTREGADO | AU8: SI | AV8: 2 | AW8: =' En tramite 23-26'!$AS8+45 -> 45994 | AX8: ENTREGADO | AY8: SI | AZ8: 2 | BA8: 45992 | BB8: SI | BC8: 2 | BD8: 45992 | BE8: =DAY(' En tramite 23-26'!$BD8) -> 1 | BF8: =TEXT(' En tramite 23-26'!$BD8,"mmmm") -> diciembre | BG8: =YEAR(' En tramite 23-26'!$BD8) -> 2025 | BH8: 1 | BI8: 2 meses 27 días | BJ8: BLOQUE 1 | BK8: P.P.E.C-BLOQUE 1 | BL8: 46211 | BM8: 2
A9: 006 | B9: 006 | C9: PC06/MATUTINO/006/2026 | D9: SÁNCHEZ MACÍAS GLORIA ALEJANDRA | E9: Sánchez Macías Gloria Alejandra | F9: 23422070060516 | G9: 4491041670 | H9: gloriasanchez17@cecyteq.edu.mx | I9: 5T0-PROG-AM | J9: MATUTINO | K9: PROGRAMACIÓN | L9: CONCLUIDO | M9: INSTITUCIÓN | N9: CECYTEQ- DIRECCIÓN GENERAL. | O9: SECTOR PÚBLICO | P9: PROYECTO DESARROLLO WEB | Q9: 4423600100 | R9: LIC. ZACARIAS OÑATE 13., COL. CIMATARIOS | S9: cgalvanb@cecyteq.edu.mx | T9: 23-26 | U9: MUJER | V9: 1 | W9: NA | X9: SI | Y9: 2 | Z9: 46035 | AA9: =DAY(Tabla1[F. INICIO]) -> 13 | AB9: =TEXT(' En tramite 23-26'!$Z9,"mmmm") -> enero | AC9: =YEAR(' En tramite 23-26'!$Z9) -> 2026 | AD9: SI | AE9: 2 | AF9: 46035 | AG9: SI | AH9: 2 | AI9: 46035 | AJ9: =DAY(' En tramite 23-26'!$AI9) -> 13 | AK9: =TEXT(' En tramite 23-26'!$AI9,"mmmm") -> enero | AL9: =YEAR(' En tramite 23-26'!$Z9) -> 2026 | AM9: SI | AN9: 2 | AO9: 46035 | AP9: SI | AQ9: 2 | AR9: 46058 | AS9: =' En tramite 23-26'!$AI9+45 -> 46080 | AT9: ENTREGADO | AU9: SI | AV9: 2 | AW9: =' En tramite 23-26'!$AS9+45 -> 46125 | AX9: ENTREGADO | AY9: SI | AZ9: 2 | BA9: 46125 | BB9: SI | BC9: 2 | BD9: 46125 | BE9: =DAY(' En tramite 23-26'!$BD9) -> 13 | BF9: =TEXT(' En tramite 23-26'!$BD9,"mmmm") -> abril | BG9: =YEAR(' En tramite 23-26'!$BD9) -> 2026 | BH9: 1 | BI9: 3 meses 0 días | BJ9: BLOQUE 1 | BK9: P.P.E.C-BLOQUE 1
A10: 007 | B10: 007 | C10: PC06/MATUTINO/007/2026 | D10: ARROYO CAMACHO GAEL ANTONIO | E10: Arroyo Camacho Gael Antonio | F10: 23422070060378 | G10: 4422993820 | H10: gaelarroyo3@cecyteq.edu.mx | I10: 5T0-PGA-AM | J10: MATUTINO | K10: PROCESOS DE GESTIÓN ADMINISTRATIVA | L10: CONCLUIDO | M10: EMPRESA | N10: MAQYPO INDUSTRIAL | O10: PEQUEÑAS EMPRESAS | P10: x | Q10: 4422100316 | R10: ALDAMA 43, FELIPE CARRILLO PUERTO | S10: maqypo.ind@gmail.com | T10: 23-26 | U10: HOMBRE | V10: 1 | W10: N/A | X10: SI | Y10: 2 | Z10: 45909 | AA10: =DAY(Tabla1[F. INICIO]) -> 9 | AB10: =TEXT(' En tramite 23-26'!$Z10,"mmmm") -> septiembre | AC10: =YEAR(' En tramite 23-26'!$Z10) -> 2025 | AD10: SI | AE10: 2 | AF10: 45909 | AG10: SI | AH10: 2 | AI10: 45909 | AJ10: =DAY(' En tramite 23-26'!$AI10) -> 9 | AK10: =TEXT(' En tramite 23-26'!$AI10,"mmmm") -> septiembre | AL10: =YEAR(' En tramite 23-26'!$Z10) -> 2025 | AM10: SI | AN10: 1 | AO10: 45909 | AP10: SI | AQ10: 1 | AR10: 45954 | AS10: =' En tramite 23-26'!$AI10+45 -> 45954 | AT10: ENTREGADO | AU10: SI | AV10: 2 | AW10: =' En tramite 23-26'!$AS10+45 -> 45999 | AX10: ENTREGADO | AY10: SI | AZ10: 2 | BA10: 46000 | BB10: SI | BC10: 2 | BD10: 46000 | BE10: =DAY(' En tramite 23-26'!$BD10) -> 9 | BF10: =TEXT(' En tramite 23-26'!$BD10,"mmmm") -> diciembre | BG10: =YEAR(' En tramite 23-26'!$BD10) -> 2025 | BH10: 1 | BI10: 4 meses 19 días | BJ10: BLOQUE 1 | BK10: P.P.E.C-BLOQUE 1 | BL10: 46211 | BM10: 2
A11: 008 | B11: 008 | C11: PC06/MATUTINO/008/2026 | D11: RAMOS DE JESÚS KARLA ESMERALDA | E11: Ramos De Jesús Karla Esmeralda | F11: 23422070060514 | G11: 4428257614 | H11: karlaramos28@cecyteq.edu.mx | I11: 5T0-PROG-AM | J11: MATUTINO | K11: PROGRAMACIÓN | L11: CONCLUIDO | M11: PROYECTO | N11: CECYTEQ-PLANTEL 6 CORREGIDORA. | O11: SECTOR PÚBLICO | P11: PROYECTO BASE DE DATOS CLINICA | Q11: 4421561235 | R11: AV. CANDILES 317., VALLE REAL RECIDENCIAL C.P.76903 CANDILES QRO. | S11: yadira.f@cecyteq.edu.mx | T11: 23-26 | U11: MUJER | V11: 1 | W11: N/A | X11: SI | Y11: 2 | Z11: 45901 | AA11: =DAY(Tabla1[F. INICIO]) -> 1 | AB11: =TEXT(' En tramite 23-26'!$Z11,"mmmm") -> septiembre | AC11: =YEAR(' En tramite 23-26'!$Z11) -> 2025 | AD11: SI | AE11: 2 | AF11: 45901 | AG11: SI | AH11: 2 | AI11: 45901 | AJ11: =DAY(' En tramite 23-26'!$AI11) -> 1 | AK11: =TEXT(' En tramite 23-26'!$AI11,"mmmm") -> septiembre | AL11: =YEAR(' En tramite 23-26'!$Z11) -> 2025 | AM11: SI | AN11: 2 | AO11: 45901 | AP11: SI | AQ11: 2 | AR11: 45978 | AS11: =' En tramite 23-26'!$AI11+45 -> 45946 | AT11: ENTREGADO | AU11: SI | AV11: 2 | AW11: 45996 | AX11: ENTREGADO | AY11: SI | AZ11: 2 | BA11: 45996 | BB11: SI | BC11: 2 | BD11: 45996 | BE11: =DAY(' En tramite 23-26'!$BD11) -> 5 | BF11: =TEXT(' En tramite 23-26'!$BD11,"mmmm") -> diciembre | BG11: =YEAR(' En tramite 23-26'!$BD11) -> 2025 | BH11: 1 | BI11: 3 meses 22 días | BJ11: BLOQUE 1 | BK11: P.P.E.C-BLOQUE 1
A12: 009 | B12: 009 | C12: PC06/MATUTINO/009/2026 | D12: GUERRERO GONZÁLEZ DIEGO FERNANDO | E12: Guerrero González Diego Fernando | F12: 23422070060488 | G12: 4424534441 | H12: diegoguerrero3@cecyteq.edu.mx | I12: 5T0-PROG-AM | J12: MATUTINO | K12: PROGRAMACIÓN | L12: CONCLUIDO | M12: PROYECTO | N12: CECYTEQ-PLANTEL 6 CORREGIDORA. | O12: SECTOR PÚBLICO | P12: PROYECTO BASE DE DATOS CLINICA | Q12: 4421561235 | R12: AV. CANDILES 317., VALLE REAL RECIDENCIAL C.P.76903 CANDILES QRO. | S12: yadira.f@cecyteq.edu.mx | T12: 23-26 | U12: HOMBRE | V12: 1 | W12: N/A | X12: SI | Y12: 2 | Z12: 45901 | AA12: =DAY(Tabla1[F. INICIO]) -> 1 | AB12: =TEXT(' En tramite 23-26'!$Z12,"mmmm") -> septiembre | AC12: =YEAR(' En tramite 23-26'!$Z12) -> 2025 | AD12: SI | AE12: 2 | AF12: 45901 | AG12: SI | AH12: 2 | AI12: 45901 | AJ12: =DAY(' En tramite 23-26'!$AI12) -> 1 | AK12: =TEXT(' En tramite 23-26'!$AI12,"mmmm") -> septiembre | AL12: =YEAR(' En tramite 23-26'!$Z12) -> 2025 | AM12: SI | AN12: 2 | AO12: 45901 | AP12: SI | AQ12: 2 | AR12: 45947 | AS12: =' En tramite 23-26'!$AI12+45 -> 45946 | AT12: ENTREGADO | AU12: SI | AV12: 2 | AW12: 45996 | AX12: ENTREGADO | AY12: SI | AZ12: 2 | BA12: 45996 | BB12: SI | BC12: 2 | BD12: 45996 | BE12: =DAY(' En tramite 23-26'!$BD12) -> 5 | BF12: =TEXT(' En tramite 23-26'!$BD12,"mmmm") -> diciembre | BG12: =YEAR(' En tramite 23-26'!$BD12) -> 2025 | BH12: 1 | BI12: 3 meses 0 días | BJ12: BLOQUE 1 | BK12: P.P.E.C-BLOQUE 1 | BL12: 46212 | BM12: 2
A13: 010 | B13: 010 | C13: PC06/MATUTINO/010/2026 | D13: MIJANGOS MORENO SAMUEL | E13: Mijangos Moreno Samuel | F13: 23422070060501 | G13: 4428119434 | H13: samuelmijangos@cecyteq.edu.mx | I13: 5T0-PROG-AM | J13: MATUTINO | K13: PROGRAMACIÓN | L13: CONCLUIDO | M13: PROYECTO | N13: CECYTEQ-PLANTEL 6 CORREGIDORA. | O13: SECTOR PÚBLICO | P13: PROYECTO BASE DE DATOS CLINICA | Q13: 4421561235 | R13: AV. CANDILES 317., VALLE REAL RECIDENCIAL C.P.76903 CANDILES QRO. | S13: yadira.f@cecyteq.edu.mx | T13: 23-26 | U13: HOMBRE | V13: 1 | W13: N/A | X13: SI | Y13: 2 | Z13: 45901 | AA13: =DAY(Tabla1[F. INICIO]) -> 1 | AB13: =TEXT(' En tramite 23-26'!$Z13,"mmmm") -> septiembre | AC13: =YEAR(' En tramite 23-26'!$Z13) -> 2025 | AD13: SI | AE13: 2 | AF13: 45901 | AG13: SI | AH13: 2 | AI13: 45901 | AJ13: =DAY(' En tramite 23-26'!$AI13) -> 1 | AK13: =TEXT(' En tramite 23-26'!$AI13,"mmmm") -> septiembre | AL13: =YEAR(' En tramite 23-26'!$Z13) -> 2025 | AM13: SI | AN13: 2 | AO13: 45901 | AP13: SI | AQ13: 2 | AR13: 45947 | AS13: =' En tramite 23-26'!$AI13+45 -> 45946 | AT13: ENTREGADO | AU13: SI | AV13: 2 | AW13: 45996 | AX13: ENTREGADO | AY13: SI | AZ13: 2 | BA13: 45996 | BB13: SI | BC13: 2 | BD13: 45996 | BE13: =DAY(' En tramite 23-26'!$BD13) -> 5 | BF13: =TEXT(' En tramite 23-26'!$BD13,"mmmm") -> diciembre | BG13: =YEAR(' En tramite 23-26'!$BD13) -> 2025 | BH13: 1 | BI13: 3 meses 0 días | BJ13: BLOQUE 1 | BK13: P.P.E.C-BLOQUE 1 | BL13: 46302 | BM13: 2
A14: 011 | B14: 011 | C14: PC06/MATUTINO/011/2026 | D14: AMADOR HERNÁNDEZ LUIS ÁNGEL | E14: Amador Hernández Luis Ángel | F14: 23422070060475 | G14: 4425641820 | H14: luisamador24@cecyteq.edu.mx | I14: 5T0-PROG-AM | J14: MATUTINO | K14: PROGRAMACIÓN | L14: CONCLUIDO | M14: EMPRESA | N14: TU CIBER ESPACIO | O14: MICROEMPRESAS | P14: x | Q14: 4421866359 | R14: AV. CANDILES 110-D., COL. LOS CANDILES | S14: soporte.espaciociber@gmail.com | T14: 23-26 | U14: HOMBRE | V14: 1 | W14: N/A | X14: SI | Y14: 2 | Z14: 45917 | AA14: =DAY(Tabla1[F. INICIO]) -> 17 | AB14: =TEXT(' En tramite 23-26'!$Z14,"mmmm") -> septiembre | AC14: =YEAR(' En tramite 23-26'!$Z14) -> 2025 | AD14: SI | AE14: 2 | AF14: 45917 | AG14: SI | AH14: 2 | AI14: 45922 | AJ14: =DAY(' En tramite 23-26'!$AI14) -> 22 | AK14: =TEXT(' En tramite 23-26'!$AI14,"mmmm") -> septiembre | AL14: =YEAR(' En tramite 23-26'!$Z14) -> 2025 | AM14: SI | AN14: 1 | AO14: 45922 | AP14: SI | AQ14: 2 | AR14: 45977 | AS14: =' En tramite 23-26'!$AI14+45 -> 45967 | AT14: ENTREGADO | AU14: SI | AV14: 2 | AW14: 46073 | AX14: ENTREGADO | AY14: SI | AZ14: 2 | BA14: 46073 | BB14: SI | BC14: 2 | BD14: 46073 | BE14: =DAY(' En tramite 23-26'!$BD14) -> 20 | BF14: =TEXT(' En tramite 23-26'!$BD14,"mmmm") -> febrero | BG14: =YEAR(' En tramite 23-26'!$BD14) -> 2026 | BH14: 1 | BI14: 4 meses y 29 días | BJ14: BLOQUE 1 | BK14: P.P.E.C-BLOQUE 1 | BL14: 46211 | BM14: 2
A15: 012 | B15: 012 | C15: PC06/MATUTINO/012/2026 | D15: OLVERA BARCENAS KEVIN EMMANUEL | E15: Olvera Barcenas Kevin Emmanuel | F15: 23422070060407 | G15: 4421804362 | H15: kevinolvera3@cecyteq.edu.mx | I15: 5T0-PGA-AM | J15: MATUTINO | K15: PROCESOS DE GESTIÓN ADMINISTRATIVA | L15: CONCLUIDO | M15: EMPRESA | N15: M&E MUEBLES Y EQUIPOS PARA OFICINA | P15: x | Q15: 4424102095 | R15: AV. UNIVERSIDAD PONIENTE 174, COL. CENTRO | S15: ameneyrow@hotmail.com | T15: 23-26 | U15: HOMBRE | V15: 2 | W15: 3200 | X15: SI | Y15: 2 | Z15: 45917 | AA15: =DAY(Tabla1[F. INICIO]) -> 17 | AB15: =TEXT(' En tramite 23-26'!$Z15,"mmmm") -> septiembre | AC15: =YEAR(' En tramite 23-26'!$Z15) -> 2025 | AD15: SI | AE15: 2 | AF15: 45917 | AG15: SI | AH15: 2 | AI15: 45917 | AJ15: =DAY(' En tramite 23-26'!$AI15) -> 17 | AK15: =TEXT(' En tramite 23-26'!$AI15,"mmmm") -> septiembre | AL15: =YEAR(' En tramite 23-26'!$Z15) -> 2025 | AM15: SI | AN15: 1 | AO15: 45917 | AP15: SI | AQ15: 1 | AR15: 45958 | AS15: =' En tramite 23-26'!$AI15+45 -> 45962 | AT15: ENTREGADO | AU15: SI | AV15: 2 | AW15: 46008 | AX15: ENTREGADO | AY15: SI | AZ15: 2 | BA15: 45996 | BB15: SI | BC15: 2 | BD15: 46008 | BE15: =DAY(' En tramite 23-26'!$BD15) -> 17 | BF15: =TEXT(' En tramite 23-26'!$BD15,"mmmm") -> diciembre | BG15: =YEAR(' En tramite 23-26'!$BD15) -> 2025 | BH15: 1 | BI15: 3 meses 19 días | BJ15: BLOQUE 1 | BK15: P.P.E.C-BLOQUE 1 | BL15: 46211 | BM15: 2
A16: 013 | D16: RIOS SÁNCHEZ CALEB UZIEL | E16: Rios Sánchez Caleb Uziel | F16: 23422070060262 | G16: 4428779061 | H16: calebrios@cecyteq.edu.mx | I16: 5T0-MECA-BM | J16: MATUTINO | K16: MECATRÓNICA | L16: EN TRAMITE | M16: INSTITUCIÓN | N16: UNIVERSIDAD TECNOLÓGICA DE QUERÉTARO | O16: SECTOR PÚBLICO | P16: x | Q16: 4422096100 | R16: AV. PIE DE LA CUESTA #2501 | S16: arturo.urbiola@uteq.edu.mx | T16: 23-26 | U16: HOMBRE | V16: 0 | X16: SI | Y16: 2 | Z16: 45911 | AA16: =DAY(Tabla1[F. INICIO]) -> 11 | AB16: =TEXT(' En tramite 23-26'!$Z16,"mmmm") -> septiembre | AC16: =YEAR(' En tramite 23-26'!$Z16) -> 2025 | AD16: SI | AE16: 2 | AF16: 45912 | AS16: =' En tramite 23-26'!$AI16+45 -> 45 | AW16: =' En tramite 23-26'!$AS16+45 -> 90
A17: 014 | B17: 013 | C17: PC06/VESPERTINO/013/2026 | D17: MATA HERRERO JOSÉ ANTONIO | E17: Mata Herrero José Antonio | F17: 23422070060546 | G17: 4421225886 | H17: josemata57@cecyteq.edu.mx | I17: 5T0-PROG-AV | J17: VESPERTINO | K17: PROGRAMACIÓN | L17: CONCLUIDO | M17: EMPRESA | N17: ALARMAS PROSECURITY | O17: MEDIANAS EMPRESAS | P17: x | Q17: 4428530301 | R17: JESÚS MA. VAZQUE CANDILES | S17: alarmaspro@hotmail.com | T17: 23-26 | U17: HOMBRE | V17: 1 | W17: N/A | X17: SI | Y17: 2 | Z17: 45910 | AA17: =DAY(Tabla1[F. INICIO]) -> 10 | AB17: =TEXT(' En tramite 23-26'!$Z17,"mmmm") -> septiembre | AC17: =YEAR(' En tramite 23-26'!$Z17) -> 2025 | AD17: SI | AE17: 2 | AF17: 45910 | AG17: SI | AH17: 2 | AI17: 45910 | AJ17: =DAY(' En tramite 23-26'!$AI17) -> 10 | AK17: =TEXT(' En tramite 23-26'!$AI17,"mmmm") -> septiembre | AL17: =YEAR(' En tramite 23-26'!$Z17) -> 2025 | AM17: SI | AN17: 2 | AO17: 45910 | AP17: SI | AQ17: 2 | AR17: 46322 | AS17: =' En tramite 23-26'!$AI17+45 -> 45955 | AT17: ENTREGADO | AU17: SI | AV17: 2 | AW17: 46029 | AX17: ENTREGADO | AY17: SI | AZ17: 2 | BA17: 46029 | BB17: SI | BC17: 2 | BD17: 46029 | BE17: =DAY(' En tramite 23-26'!$BD17) -> 7 | BF17: =TEXT(' En tramite 23-26'!$BD17,"mmmm") -> enero | BG17: =YEAR(' En tramite 23-26'!$BD17) -> 2026 | BH17: 1 | BI17: 3 meses y 28 días | BJ17: BLOQUE 1 | BK17: P.P.E.C-BLOQUE 1
A18: 15 | D18: NAVARRO TOLEDO JOSÉ ALEJANDRO | E18: Navarro Toledo José Alejandro | F18: 23422070060 504 | G18: 4423769604 | H18: josenavarro66@cecyteq.edu.mx | I18: 5T0-PROG-AM | J18: MATUTINO | K18: PROGRAMACIÓN | L18: EN TRAMITE | M18: PROYECTO | N18: CECYTEQ-PLANTEL 6 | O18: SECTOR PÚBLICO | P18: PROYECTO BASE DE DATOS CLINICA | Q18: 4421561235 | R18: AV. CANDILES 317., VALLE REAL RECIDENCIAL C.P.76903 CANDILES QRO. | S18: yadira.f@cecyteq.edu.mx | T18: 23-26 | U18: HOMBRE | V18: 0 | X18: NO | Y18: 0 | AS18: =' En tramite 23-26'!$AI18+45 -> 45 | AW18: =' En tramite 23-26'!$AS18+45 -> 90
A19: 016 | B19: 014 | C19: PC06/MATUTINO/014/2026 | D19: NIEVES ARIAS MARÍA FERNANDA | E19: Nieves Arias María Fernanda | F19: 23422070060131 | G19: 4427166846 | H19: marianieves11@cecyteq.edu.mx | I19: 5T0-LOG-AM | J19: MATUTINO | K19: LOGÍSTICA | L19: CONCLUIDO | M19: EMPRESA | N19: DSA MAQUINADOS INDUSTRIALES S. DE R.L. DE C.V. | O19: PEQUEÑAS EMPRESAS | P19: x | Q19: 4423935390 | R19: CALLE SAN MATEO S/N, EL ROSARIO | S19: dsamaquinados@gmail.com | T19: 23-26 | U19: MUJER | V19: 1 | W19: N/A | X19: SI | Y19: 2 | Z19: 45919 | AA19: =DAY(Tabla1[F. INICIO]) -> 19 | AB19: =TEXT(' En tramite 23-26'!$Z19,"mmmm") -> septiembre | AC19: =YEAR(' En tramite 23-26'!$Z19) -> 2025 | AD19: SI | AE19: 2 | AF19: 45923 | AG19: SI | AH19: 2 | AI19: 45923 | AJ19: =DAY(' En tramite 23-26'!$AI19) -> 23 | AK19: =TEXT(' En tramite 23-26'!$AI19,"mmmm") -> septiembre | AL19: =YEAR(' En tramite 23-26'!$Z19) -> 2025 | AM19: SI | AN19: 1 | AO19: 45923 | AP19: SI | AQ19: 2 | AR19: 46006 | AS19: =' En tramite 23-26'!$AI19+45 -> 45968 | AT19: ENTREGADO | AU19: SI | AV19: 2 | AW19: 46038 | AX19: ENTREGADO | AY19: SI | AZ19: 2 | BA19: 46038 | BB19: SI | BC19: 2 | BD19: 46038 | BE19: =DAY(' En tramite 23-26'!$BD19) -> 16 | BF19: =TEXT(' En tramite 23-26'!$BD19,"mmmm") -> enero | BG19: =YEAR(' En tramite 23-26'!$BD19) -> 2026 | BH19: 1 | BI19: 3 meses 17 días | BJ19: BLOQUE 1 | BK19: P.P.E.C-BLOQUE 1 | BL19: 46211 | BM19: 2
A20: 017 | B20: 015 | C20: PC06/MATUTINO/015/2026 | D20: HERNÁNDEZ GARCÍA MARÍA JOSÉ | E20: Hernández García María José | F20: 23422070060063 | G20: 4421500768 | H20: maria.jose@cecyteq.edu.mx | I20: 5T0-BIO-AM | J20: MATUTINO | K20: BIOTECNOLOGÍA | L20: CONCLUIDO | M20: PROYECTO | N20: CECYTEQ-PLANTEL 6 CORREGIDORA. | O20: SECTOR PÚBLICO | P20: PROYECTO DE ELECTRO GERMINACIÓN DE BIZNAGA, BARRIL Y ACITRÓN CON BIOCARBONO | Q20: 4421550768 | R20: AV. CANDILES 317., VALLE REAL RECIDENCIAL C.P.76903 CANDILES QRO. | S20: teresa.r@cecyteq.edu.mx | T20: 23-26 | U20: MUJER | V20: 1 | W20: N/A | X20: SI | Y20: 2 | Z20: 45881 | AA20: =DAY(Tabla1[F. INICIO]) -> 12 | AB20: =TEXT(' En tramite 23-26'!$Z20,"mmmm") -> agosto | AC20: =YEAR(' En tramite 23-26'!$Z20) -> 2025 | AD20: SI | AE20: 2 | AF20: 45881 | AG20: SI | AH20: 2 | AI20: 45881 | AJ20: =DAY(' En tramite 23-26'!$AI20) -> 12 | AK20: =TEXT(' En tramite 23-26'!$AI20,"mmmm") -> agosto | AL20: =YEAR(' En tramite 23-26'!$Z20) -> 2025 | AM20: SI | AN20: 2 | AO20: 45881 | AP20: SI | AQ20: 2 | AR20: 45926 | AS20: =' En tramite 23-26'!$AI20+45 -> 45926 | AT20: ENTREGADO | AU20: SI | AV20: 2 | AW20: =' En tramite 23-26'!$AS20+45 -> 45971 | AX20: ENTREGADO | AY20: SI | AZ20: 2 | BA20: 45971 | BB20: SI | BC20: 2 | BD20: 45971 | BE20: =DAY(' En tramite 23-26'!$BD20) -> 10 | BF20: =TEXT(' En tramite 23-26'!$BD20,"mmmm") -> noviembre | BG20: =YEAR(' En tramite 23-26'!$BD20) -> 2025 | BH20: 1 | BI20: 2 meses 29 días | BJ20: BLOQUE 1 | BK20: P.P.E.C-BLOQUE 1 | BL20: 46211 | BM20: 2
A21: 018 | B21: 016 | C21: PC06/MATUTINO/016/2026 | D21: MORALES ORTIZ DANIEL | E21: Morales Ortiz Daniel | F21: 23422070060503 | G21: 4461026039 | H21: danielmorales79@cecyteq.edu.mx | I21: 5T0-PROG-AM | J21: MATUTINO | K21: PROGRAMACIÓN | L21: CONCLUIDO | M21: PROYECTO | N21: CECYTEQ-PLANTEL 6 CORREGIDORA. | O21: SECTOR PÚBLICO | P21: PROYECTO " ASESORÍAS MATEMÁTICAS 1" | Q21: 4421561235 | R21: AV. CANDILES 317., VALLE REAL RECIDENCIAL C.P.76903 CANDILES QRO. | S21: yadira.f@cecyteq.edu.mx | T21: 23-26 | U21: HOMBRE | V21: 1 | W21: N/A | X21: SI | Y21: 2 | Z21: 46076 | AA21: =DAY(Tabla1[F. INICIO]) -> 23 | AB21: =TEXT(' En tramite 23-26'!$Z21,"mmmm") -> febrero | AC21: =YEAR(' En tramite 23-26'!$Z21) -> 2026 | AD21: SI | AE21: 3 | AF21: 46076 | AG21: SI | AH21: 3 | AI21: 46076 | AJ21: =DAY(' En tramite 23-26'!$AI21) -> 23 | AK21: =TEXT(' En tramite 23-26'!$AI21,"mmmm") -> febrero | AL21: =YEAR(' En tramite 23-26'!$Z21) -> 2026 | AM21: SI | AN21: 3 | AO21: 46076 | AP21: SI | AQ21: 2 | AR21: 46121 | AS21: =' En tramite 23-26'!$AI21+45 -> 46121 | AT21: ENTREGADO | AU21: SI | AV21: 2 | AW21: 46168 | AX21: ENTREGADO | AY21: SI | AZ21: 2 | BA21: 46168 | BB21: SI | BC21: 2 | BD21: 46168 | BE21: =DAY(' En tramite 23-26'!$BD21) -> 26 | BF21: =TEXT(' En tramite 23-26'!$BD21,"mmmm") -> mayo | BG21: =YEAR(' En tramite 23-26'!$BD21) -> 2026 | BH21: 1 | BI21: 3 meses y 3 días | BJ21: BLOQUE 1 | BK21: P.P.E.C-BLOQUE 1
A22: 019 | B22: 017 | C22: PC06/MATUTINO/017/2026 | D22: ESTRELLA GÓMEZ PEDRO EMILIO | E22: Estrella Gómez Pedro Emilio | F22: 23422070060386 | G22: 4425264969 | H22: pedroestrellagomez@cecyteq.edu.mx | I22: 5T0-PGA-AM | J22: MATUTINO | K22: PROCESOS DE GESTIÓN ADMINISTRATIVA | L22: CONCLUIDO | M22: EMPRESA | N22: M&E MUEBLES Y EQUIPOS PARA OFICINA | O22: MEDIANAS EMPRESAS | P22: x | Q22: 4428114091 | R22: AV. UNIVERSIDAD PONIENTE 174, COL. CENTRO | S22: ameneyrow@hotmail.com | T22: 23-26 | U22: HOMBRE | V22: 2 | W22: =800*4 -> 3200 | X22: SI | Y22: 3 | Z22: 45923 | AA22: =DAY(Tabla1[F. INICIO]) -> 23 | AB22: =TEXT(' En tramite 23-26'!$Z22,"mmmm") -> septiembre | AC22: =YEAR(' En tramite 23-26'!$Z22) -> 2025 | AD22: SI | AE22: 2 | AF22: 45923 | AG22: SI | AH22: 2 | AI22: 45924 | AJ22: =DAY(' En tramite 23-26'!$AI22) -> 24 | AK22: =TEXT(' En tramite 23-26'!$AI22,"mmmm") -> septiembre | AL22: =YEAR(' En tramite 23-26'!$Z22) -> 2025 | AM22: SI | AN22: 3 | AO22: 45930 | AP22: SI | AQ22: 3 | AR22: 45985 | AS22: =' En tramite 23-26'!$AI22+45 -> 45969 | AT22: ENTREGADO | AU22: SI | AV22: 2 | AW22: 46380 | AX22: ENTREGADO | AY22: SI | AZ22: 2 | BA22: 46380 | BB22: SI | BC22: 2 | BD22: 46015 | BE22: =DAY(' En tramite 23-26'!$BD22) -> 24 | BF22: =TEXT(' En tramite 23-26'!$BD22,"mmmm") -> diciembre | BG22: =YEAR(' En tramite 23-26'!$BD22) -> 2025 | BH22: 1 | BI22: 3 meses 0 días | BJ22: BLOQUE 1 | BK22: P.P.E.C-BLOQUE 1
A23: 020 | D23: LUNA MARTÍNEZ GIOVANI ALEJANDRO | E23: Luna Martínez Giovani Alejandro | F23: 23422070060 402 | G23: 4421607262 | H23: giovaniluna@cecyteq.edu.mx | I23: 5T0-PGA-AM | J23: MATUTINO | K23: PROCESOS DE GESTIÓN ADMINISTRATIVA | L23: EN TRAMITE | M23: EMPRESA | N23: MINISUPER JAOEHJ | O23: MICROEMPRESAS | P23: x | Q23: 4427116464 | R23: LOMA DE LA CAÑADA | S23: minisuperjapehj@gmail.com | T23: 23-26 | U23: HOMBRE | V23: 0 | X23: SI | Y23: 2 | Z23: 45930 | AA23: =DAY(Tabla1[F. INICIO]) -> 30 | AB23: =TEXT(' En tramite 23-26'!$Z23,"mmmm") -> septiembre | AC23: =YEAR(' En tramite 23-26'!$Z23) -> 2025 | AD23: SI | AE23: 2 | AF23: 45930 | AG23: NO | AH23: 1 | AS23: =' En tramite 23-26'!$AI23+45 -> 45 | AW23: =' En tramite 23-26'!$AS23+45 -> 90
A24: 021 | B24: 018 | C24: PC06/MATUTINO/018/2026 | D24: VELÁZQUEZ ALVAREZ MARIO IVAN | E24: Velázquez Alvarez Mario Ivan | F24: 23422070060 420 | G24: 4425791027 | H24: mariovelazquez6@cecyteq.edu.mx | I24: 5T0-PGA-AM | J24: MATUTINO | K24: PROCESOS DE GESTIÓN ADMINISTRATIVA | L24: CONCLUIDO | M24: INSTITUCIÓN | N24: SECRETARIA DEL DEPORTE MUNICIPIO DE QUERÉTARO | O24: SECTOR PÚBLICO | P24: x | Q24: 4425791027 | R24: CALLE ANTONIO CARRANZA 100 | S24: antonio.rangel@municipiodequeretaro.gob.mx | T24: 23-26 | U24: HOMBRE | V24: 1 | W24: N/A | X24: SI | Y24: 2 | Z24: 45937 | AA24: =DAY(Tabla1[F. INICIO]) -> 7 | AB24: =TEXT(' En tramite 23-26'!$Z24,"mmmm") -> octubre | AC24: =YEAR(' En tramite 23-26'!$Z24) -> 2025 | AD24: SI | AE24: 2 | AF24: 45937 | AG24: SI | AH24: 2 | AI24: 45957 | AJ24: =DAY(' En tramite 23-26'!$AI24) -> 27 | AK24: =TEXT(' En tramite 23-26'!$AI24,"mmmm") -> octubre | AL24: =YEAR(' En tramite 23-26'!$Z24) -> 2025 | AM24: SI | AN24: 2 | AO24: 46322 | AP24: SI | AQ24: 2 | AR24: 46002 | AS24: =' En tramite 23-26'!$AI24+45 -> 46002 | AT24: ENTREGADO | AU24: SI | AV24: 2 | AW24: 46038 | AX24: ENTREGADO | AY24: SI | AZ24: 2 | BA24: 46038 | BB24: SI | BC24: 2 | BD24: 46038 | BE24: =DAY(' En tramite 23-26'!$BD24) -> 16 | BF24: =TEXT(' En tramite 23-26'!$BD24,"mmmm") -> enero | BG24: =YEAR(' En tramite 23-26'!$BD24) -> 2026 | BH24: 1 | BI24: 2 meses y 20 días. | BJ24: BLOQUE 1 | BK24: P.P.E.C-BLOQUE 1 | BL24: 46210 | BM24: 2
A25: 022 | D25: OLVERA ZAMORA DIANA LIZETH | E25: Olvera Zamora Diana Lizeth | F25: 23422070060 408 | G25: 4427798301 | H25: dianaolvera1@cecyteq.edu.mx | I25: 5T0-PGA-AM | J25: MATUTINO | K25: PROCESOS DE GESTIÓN ADMINISTRATIVA | L25: CONCLUIDO | M25: EMPRESA | N25: HEMIBASA | O25: PEQUEÑAS EMPRESAS | P25: x | Q25: 4427798301 | R25: ART.27 CONSTITUCIONAL 9, CASA BLANCA | S25: hemibasa@hemibasa.com.mx | T25: 23-26 | U25: MUJER | V25: 2 | W25: 4000 | X25: SI | Y25: 2 | Z25: 45951 | AA25: =DAY(Tabla1[F. INICIO]) -> 21 | AB25: =TEXT(' En tramite 23-26'!$Z25,"mmmm") -> octubre | AC25: =YEAR(' En tramite 23-26'!$Z25) -> 2025 | AD25: SI | AE25: 2 | AF25: 45951 | AG25: SI | AH25: 2 | AI25: 45951 | AJ25: =DAY(' En tramite 23-26'!$AI25) -> 21 | AK25: =TEXT(' En tramite 23-26'!$AI25,"mmmm") -> octubre | AL25: =YEAR(' En tramite 23-26'!$Z25) -> 2025 | AM25: SI | AN25: 2 | AO25: 45951 | AP25: SI | AQ25: 2 | AR25: 45998 | AS25: =' En tramite 23-26'!$AI25+45 -> 45996 | AT25: ENTREGADO | AU25: SI | AV25: 2 | AW25: 46077 | AX25: ENTREGADO | AY25: SI | AZ25: 2 | BA25: 46077 | BB25: SI | BC25: 2 | BD25: 46077 | BE25: =DAY(' En tramite 23-26'!$BD25) -> 24 | BF25: =TEXT(' En tramite 23-26'!$BD25,"mmmm") -> febrero | BG25: =YEAR(' En tramite 23-26'!$BD25) -> 2026 | BJ25: BLOQUE 2 | BK25: P.P.E.C-BLOQUE 1-2
A26: 023 | B26: 019 | C26: PC06/VESPERTINO/019/2026 | D26: ALVAREZ FRANCO DIEGO | E26: Alvarez Franco Diego | F26: 23422070060 327 | G26: N/A | H26: diegoalvarez5@gmail.com | I26: 5T0-MECA-BM | J26: VESPERTINO | K26: MECATRÓNICA | L26: CONCLUIDO | M26: EMPRESA | N26: RENTARIA EDIFICACIÓN Y ESTRUCTURA | P26: x | Q26: 4428635970 | R26: EUCALIPOS 1 BODEGA 38 LOS OLVERA | S26: Lrenteria@redes-mx.com | T26: 23-26 | U26: HOMBRE | V26: 2 | W26: 2000 | X26: SI | Y26: 2 | Z26: 45950 | AA26: =DAY(Tabla1[F. INICIO]) -> 20 | AB26: =TEXT(' En tramite 23-26'!$Z26,"mmmm") -> octubre | AC26: =YEAR(' En tramite 23-26'!$Z26) -> 2025 | AD26: SI | AE26: 2 | AF26: 45950 | AG26: SI | AH26: 2 | AI26: 45950 | AJ26: =DAY(' En tramite 23-26'!$AI26) -> 20 | AK26: =TEXT(' En tramite 23-26'!$AI26,"mmmm") -> octubre | AL26: =YEAR(' En tramite 23-26'!$Z26) -> 2025 | AM26: SI | AN26: 2 | AO26: 45950 | AP26: SI | AQ26: 2 | AR26: 46001 | AS26: 46366 | AT26: ENTREGADO | AU26: SI | AV26: 2 | AW26: 46042 | AX26: ENTREGADO | AY26: SI | AZ26: 2 | BA26: 46042 | BB26: SI | BC26: 2 | BD26: 46042 | BE26: =DAY(' En tramite 23-26'!$BD26) -> 20 | BF26: =TEXT(' En tramite 23-26'!$BD26,"mmmm") -> enero | BG26: =YEAR(' En tramite 23-26'!$BD26) -> 2026 | BH26: 1 | BI26: 3 meses | BJ26: BLOQUE 1 | BK26: P.P.E.C-BLOQUE 1
A27: 024 | B27: 020 | C27: PC06/MATUTINO/020/2026 | D27: TORREJÓN HERNÁNDEZ SANDRA LUCIA | E27: Torrejón Hernández Sandra Lucia | F27: 23422070060 418 | G27: 4421075401 | H27: sandratorrejon@cecyteq.edu.mx | I27: 5T0-PGA-AM | J27: MATUTINO | K27: PROCESOS DE GESTIÓN ADMINISTRATIVA | L27: CONCLUIDO | M27: EMPRESA | N27: R MECÁNICOS | O27: PEQUEÑAS EMPRESAS | P27: x | Q27: 4425982749 | R27: CALLE CHIAPAS 3 | S27: rafaelcelmapalacios@gmail.com | T27: 23-26 | U27: MUJER | V27: 1 | W27: N/A | X27: SI | Y27: 2 | Z27: 45932 | AA27: =DAY(Tabla1[F. INICIO]) -> 2 | AB27: =TEXT(' En tramite 23-26'!$Z27,"mmmm") -> octubre | AC27: =YEAR(' En tramite 23-26'!$Z27) -> 2025 | AD27: SI | AE27: 2 | AF27: 45932 | AG27: SI | AH27: 2 | AI27: 45933 | AJ27: =DAY(' En tramite 23-26'!$AI27) -> 3 | AK27: =TEXT(' En tramite 23-26'!$AI27,"mmmm") -> octubre | AL27: =YEAR(' En tramite 23-26'!$Z27) -> 2025 | AM27: SI | AN27: 2 | AO27: 45933 | AP27: SI | AQ27: 2 | AR27: 45979 | AS27: =' En tramite 23-26'!$AI27+45 -> 45978 | AT27: ENTREGADO | AU27: SI | AV27: 2 | AW27: 46025 | AX27: ENTREGADO | AY27: SI | AZ27: 2 | BA27: 46025 | BB27: SI | BC27: 2 | BD27: 46025 | BE27: =DAY(' En tramite 23-26'!$BD27) -> 3 | BF27: =TEXT(' En tramite 23-26'!$BD27,"mmmm") -> enero | BG27: =YEAR(' En tramite 23-26'!$BD27) -> 2026 | BH27: 1 | BI27: 3 meses | BJ27: BLOQUE 1 | BK27: P.P.E.C-BLOQUE 1 | BL27: 46210 | BM27: 2
A28: 025 | B28: 021 | C28: PC06/MATUTINO/021/2026 | D28: CECILIANO MORALES GIOVANNI | E28: Ceciliano Morales Giovanni | F28: 23422070060 436 | G28: 4425058220 | H28: giovanniceciliano@cecyteq.edu.mx | I28: 5T0-PGA-AM | J28: MATUTINO | K28: PROCESOS DE GESTIÓN ADMINISTRATIVA | L28: CONCLUIDO | M28: EMPRESA | N28: TAQUERIA DANY | O28: MICROEMPRESAS | P28: x | Q28: 4427759780 | R28: CALLE MARIA TRICHELO COL. UNIÓN 33 | S28: taqueriadany01@gmail.com | T28: 23-26 | U28: HOMBRE | V28: 1 | W28: N/A | X28: SI | Y28: 2 | Z28: 45945 | AA28: =DAY(Tabla1[F. INICIO]) -> 15 | AB28: =TEXT(' En tramite 23-26'!$Z28,"mmmm") -> octubre | AC28: =YEAR(' En tramite 23-26'!$Z28) -> 2025 | AD28: SI | AE28: 2 | AF28: 45945 | AG28: SI | AH28: 2 | AI28: 45945 | AJ28: =DAY(' En tramite 23-26'!$AI28) -> 15 | AK28: =TEXT(' En tramite 23-26'!$AI28,"mmmm") -> octubre | AL28: =YEAR(' En tramite 23-26'!$Z28) -> 2025 | AM28: SI | AN28: 2 | AO28: 45949 | AP28: SI | AQ28: 2 | AR28: 45997 | AS28: =' En tramite 23-26'!$AI28+45 -> 45990 | AT28: ENTREGADO | AU28: SI | AV28: 2 | AW28: 06/03./2026 | AX28: ENTREGADO | AY28: SI | AZ28: 2 | BA28: 46087 | BB28: SI | BC28: 2 | BD28: 46087 | BE28: =DAY(' En tramite 23-26'!$BD28) -> 6 | BF28: =TEXT(' En tramite 23-26'!$BD28,"mmmm") -> marzo | BG28: =YEAR(' En tramite 23-26'!$BD28) -> 2026 | BH28: 1 | BI28: 4 meses 19 días | BJ28: BLOQUE 1 | BK28: P.P.E.C-BLOQUE 1
A29: 026 | B29: 022 | C29: PC06/MATUTINO/022/2026 | D29: FLORES CAMACHO DANA PAOLA | E29: Flores Camacho Dana Paola | F29: 23422070060 387 | G29: 4426790947 | H29: danaflores6@cecyteq.edu.mx | I29: 5T0-PGA-AM | J29: MATUTINO | K29: PROCESOS DE GESTIÓN ADMINISTRATIVA | L29: CONCLUIDO | M29: EMPRESA | N29: GRUPO VAGAQUER S.A DE C.V | O29: MEDIANAS EMPRESAS | P29: x | Q29: 4422314351 | R29: CALLE PROGRESO 102 COL.EJIDO EL ORGANAL | S29: servicio.vazquez.admon@gmail.com | T29: 23-26 | U29: MUJER | V29: 1 | W29: N/A | X29: SI | Y29: 2 | Z29: 45883 | AA29: =DAY(Tabla1[F. INICIO]) -> 14 | AB29: =TEXT(' En tramite 23-26'!$Z29,"mmmm") -> agosto | AC29: =YEAR(' En tramite 23-26'!$Z29) -> 2025 | AD29: SI | AE29: 2 | AF29: 45883 | AG29: SI | AH29: 2 | AI29: 45950 | AJ29: =DAY(' En tramite 23-26'!$AI29) -> 20 | AK29: =TEXT(' En tramite 23-26'!$AI29,"mmmm") -> octubre | AL29: =YEAR(' En tramite 23-26'!$Z29) -> 2025 | AM29: SI | AN29: 2 | AO29: 45950 | AP29: SI | AQ29: 2 | AR29: 45996 | AS29: =' En tramite 23-26'!$AI29+45 -> 45995 | AT29: ENTREGADO | AU29: SI | AV29: 2 | AW29: 46038 | AX29: ENTREGADO | AY29: SI | AZ29: 2 | BA29: 46038 | BB29: SI | BC29: 2 | BD29: 46038 | BE29: =DAY(' En tramite 23-26'!$BD29) -> 16 | BF29: =TEXT(' En tramite 23-26'!$BD29,"mmmm") -> enero | BG29: =YEAR(' En tramite 23-26'!$BD29) -> 2026 | BH29: 1 | BI29: 2 meses 27 días | BJ29: BLOQUE 1 | BK29: P.P.E.C-BLOQUE 1
A30: 027 | D30: BEÑA ANDALÓN CARLOS ANTONIO | E30: Beña Andalón Carlos Antonio | F30: 23422070060 431 | G30: 4428639853 | H30: carlosbrena@cecyteq.edu.mx | I30: 5T0-PGA-AV | J30: VESPERTINO | K30: PROCESOS DE GESTIÓN ADMINISTRATIVA | L30: CONCLUIDO | M30: EMPRESA | N30: FIXMART DE MÉXICO | O30: MEDIANAS EMPRESAS | P30: x | Q30: 4428639853 | R30: ACCESO A CANDILES 542 INT 18 | S30: soporte@fixmart.mx | T30: 23-26 | U30: HOMBRE | V30: 0 | X30: SI | Y30: 2 | Z30: 45954 | AA30: =DAY(Tabla1[F. INICIO]) -> 24 | AB30: =TEXT(' En tramite 23-26'!$Z30,"mmmm") -> octubre | AC30: =YEAR(' En tramite 23-26'!$Z30) -> 2025 | AD30: SI | AE30: 2 | AF30: 45957 | AG30: SI | AH30: 2 | AI30: 45957 | AJ30: =DAY(' En tramite 23-26'!$AI30) -> 27 | AK30: =TEXT(' En tramite 23-26'!$AI30,"mmmm") -> octubre | AL30: =YEAR(' En tramite 23-26'!$Z30) -> 2025 | AM30: SI | AN30: 2 | AO30: 45957 | AP30: SI | AQ30: 2 | AR30: 46003 | AS30: =' En tramite 23-26'!$AI30+45 -> 46002 | AT30: ENTREGADO | AU30: SI | AV30: 2 | AW30: 46049 | AX30: ENTREGADO | AY30: SI | AZ30: 2 | BA30: 46049 | BB30: SI | BC30: 2 | BD30: 46049 | BE30: =DAY(' En tramite 23-26'!$BD30) -> 27 | BF30: =TEXT(' En tramite 23-26'!$BD30,"mmmm") -> enero | BG30: =YEAR(' En tramite 23-26'!$BD30) -> 2026 | BJ30: BLOQUE 2 | BK30: P.P.E.C-BLOQUE 1-2
A31: 028 | B31: 023 | C31: PC06/VESPERTINO/023/2026 | D31: REYES GARCÍA CARLOS | E31: Reyes García Carlos | F31: 23422070060 465 | G31: 4425995199 | H31: carlosreyes114@cecyteq.edu.mx | I31: 5T0-PGA-AV | J31: VESPERTINO | K31: PROCESOS DE GESTIÓN ADMINISTRATIVA | L31: CONCLUIDO | M31: EMPRESA | N31: FIXMART DE MÉXICO | O31: MEDIANAS EMPRESAS | P31: x | Q31: 4428639853 | R31: ACCESO A CANDILES 542 INT 18 | S31: soporte@fixmart.mx | T31: 23-26 | U31: HOMBRE | V31: 1 | W31: N/A | X31: SI | Y31: 2 | Z31: 45954 | AA31: =DAY(Tabla1[F. INICIO]) -> 24 | AB31: =TEXT(' En tramite 23-26'!$Z31,"mmmm") -> octubre | AC31: =YEAR(' En tramite 23-26'!$Z31) -> 2025 | AD31: SI | AE31: 2 | AF31: 45954 | AG31: SI | AH31: 2 | AI31: 45957 | AJ31: =DAY(' En tramite 23-26'!$AI31) -> 27 | AK31: =TEXT(' En tramite 23-26'!$AI31,"mmmm") -> octubre | AL31: =YEAR(' En tramite 23-26'!$Z31) -> 2025 | AM31: SI | AN31: 2 | AO31: 46322 | AP31: SI | AQ31: 2 | AR31: 46003 | AS31: =' En tramite 23-26'!$AI31+45 -> 46002 | AT31: ENTREGADO | AU31: SI | AV31: 2 | AW31: 46049 | AX31: ENTREGADO | AY31: SI | AZ31: 2 | BA31: 46049 | BB31: SI | BC31: 2 | BD31: 46049 | BE31: =DAY(' En tramite 23-26'!$BD31) -> 27 | BF31: =TEXT(' En tramite 23-26'!$BD31,"mmmm") -> enero | BG31: =YEAR(' En tramite 23-26'!$BD31) -> 2026 | BH31: 1 | BI31: 3 meses | BJ31: BLOQUE 1 | BK31: P.P.E.C-BLOQUE 1
A32: 029 | B32: 024 | C32: PC06/MATUTINO/024/2026 | D32: SEGUNDO LÓPEZ GIOVANNI IMANOL | E32: Segundo López Giovanni Imanol | F32: 23422070060 416 | G32: 4426560152 | H32: giovannisegundo@cecyteq.edu.mx | I32: 5T0-PGA-AM | J32: MATUTINO | K32: PROCESOS DE GESTIÓN ADMINISTRATIVA | L32: CONCLUIDO | M32: EMPRESA | N32: ORMEN S.A DE C.V | O32: MEDIANAS EMPRESAS | P32: x | Q32: 4426560152 | R32: TRATOLI 28 COL. SANTUARIOS EL CERRITO | S32: aaronmichel.ormen@gmail.com | T32: 23-26 | U32: HOMBRE | V32: 2 | W32: 10000 | X32: SI | Y32: 2 | Z32: 45951 | AA32: =DAY(Tabla1[F. INICIO]) -> 21 | AB32: =TEXT(' En tramite 23-26'!$Z32,"mmmm") -> octubre | AC32: =YEAR(' En tramite 23-26'!$Z32) -> 2025 | AD32: SI | AE32: 2 | AF32: 45958 | AG32: SI | AH32: 2 | AI32: 45964 | AJ32: =DAY(' En tramite 23-26'!$AI32) -> 3 | AK32: =TEXT(' En tramite 23-26'!$AI32,"mmmm") -> noviembre | AL32: =YEAR(' En tramite 23-26'!$Z32) -> 2025 | AM32: SI | AN32: 2 | AO32: 45964 | AP32: SI | AQ32: 2 | AR32: 46368 | AS32: =' En tramite 23-26'!$AI32+45 -> 46009 | AT32: ENTREGADO | AU32: SI | AV32: 2 | AW32: 46076 | AX32: ENTREGADO | AY32: SI | AZ32: 2 | BA32: 46076 | BB32: SI | BC32: 2 | BD32: 46076 | BE32: =DAY(' En tramite 23-26'!$BD32) -> 23 | BF32: =TEXT(' En tramite 23-26'!$BD32,"mmmm") -> febrero | BG32: =YEAR(' En tramite 23-26'!$BD32) -> 2026 | BH32: 1 | BI32: 3 meses y 20 días | BJ32: BLOQUE 1 | BK32: P.P.E.C-BLOQUE 1 | BL32: 46212 | BM32: 2
A33: 030 | B33: 025 | C33: PC06/VESPERTINO/025/2026 | D33: FLYNN TORRES XIMENA ELIZABETH | E33: Flynn Torres Ximena Elizabeth | F33: 23422070060 614 | G33: 4461140433 | H33: ximena.f@cecyteq.edu.mx | I33: 5T0-MECA-AV | J33: VESPERTINO | K33: MECATRÓNICA | L33: CONCLUIDO | M33: EMPRESA | N33: FABRICACIONES CNC DE QUERÉTARO S.A. DE C.V | P33: x | Q33: 4422281206 | R33: MONTERREY 17 SAN JOSÉ | S33: recurso.humano@fabricaciones cnc.com | T33: 23-26 | U33: MUJER | V33: 1 | W33: N/A | X33: SI | Y33: 2 | Z33: 45957 | AA33: =DAY(Tabla1[F. INICIO]) -> 27 | AB33: =TEXT(' En tramite 23-26'!$Z33,"mmmm") -> octubre | AC33: =YEAR(' En tramite 23-26'!$Z33) -> 2025 | AD33: SI | AE33: 2 | AF33: 45957 | AG33: SI | AH33: 2 | AI33: 45964 | AJ33: =DAY(' En tramite 23-26'!$AI33) -> 3 | AK33: =TEXT(' En tramite 23-26'!$AI33,"mmmm") -> noviembre | AL33: =YEAR(' En tramite 23-26'!$Z33) -> 2025 | AM33: SI | AN33: 2 | AO33: 45964 | AP33: SI | AQ33: 2 | AR33: 46009 | AS33: =' En tramite 23-26'!$AI33+45 -> 46009 | AT33: ENTREGADO | AU33: SI | AV33: 2 | AW33: 46056 | AX33: ENTREGADO | AY33: SI | AZ33: 2 | BA33: 46056 | BB33: SI | BC33: 2 | BD33: 46056 | BE33: =DAY(' En tramite 23-26'!$BD33) -> 3 | BF33: =TEXT(' En tramite 23-26'!$BD33,"mmmm") -> febrero | BG33: =YEAR(' En tramite 23-26'!$BD33) -> 2026 | BH33: 1 | BI33: 3 meses | BJ33: BLOQUE 1 | BK33: P.P.E.C-BLOQUE 1 | BL33: 46211 | BM33: 2
A34: 031 | B34: 026 | C34: PC06/MATUTINO/026/2026 | D34: MERCADO ROMERO JUAN PABLO | E34: Mercado Romero Juan Pablo | F34: 23422070060 030 | G34: 4427535657 | H34: juanmercado18@cecyteq.edu.mx | I34: 5T0-BIO-AM | J34: MATUTINO | K34: BIOTECNOLOGÍA | L34: CONCLUIDO | M34: PROYECTO | N34: CECYTEQ-PLANTEL 6 CORREGIDORA | O34: SECTOR PÚBLICO | P34: PROYECTO | Q34: 4421477241 | R34: AV. CANDILES 317., VALLE REAL RECIDENCIAL C.P.76903 CANDILES QRO. | S34: teresa.r@cecyteq.edu.mx | T34: 23-26 | U34: HOMBRE | V34: 1 | W34: N/A | X34: SI | Y34: 2 | Z34: 45930 | AA34: =DAY(Tabla1[F. INICIO]) -> 30 | AB34: =TEXT(' En tramite 23-26'!$Z34,"mmmm") -> septiembre | AC34: =YEAR(' En tramite 23-26'!$Z34) -> 2025 | AD34: SI | AE34: 2 | AF34: 45930 | AG34: SI | AH34: 2 | AI34: 45930 | AJ34: =DAY(' En tramite 23-26'!$AI34) -> 30 | AK34: =TEXT(' En tramite 23-26'!$AI34,"mmmm") -> septiembre | AL34: =YEAR(' En tramite 23-26'!$Z34) -> 2025 | AM34: SI | AN34: 2 | AO34: 45930 | AP34: SI | AQ34: 2 | AR34: 45975 | AS34: =' En tramite 23-26'!$AI34+45 -> 45975 | AT34: ENTREGADO | AU34: SI | AV34: 2 | AW34: 46083 | AX34: ENTREGADO | AY34: SI | AZ34: 2 | BA34: 46083 | BB34: SI | BC34: 2 | BD34: 46083 | BE34: =DAY(' En tramite 23-26'!$BD34) -> 2 | BF34: =TEXT(' En tramite 23-26'!$BD34,"mmmm") -> marzo | BG34: =YEAR(' En tramite 23-26'!$BD34) -> 2026 | BH34: 1 | BI34: 5 meses 1 día | BJ34: BLOQUE 1 | BK34: P.P.E.C-BLOQUE 1 | BL34: 46210 | BM34: 2
A35: 032 | B35: 027 | C35: PC06/MATUTINO/027/2026 | D35: RESENDIZ REYES NATALIA | E35: Resendiz Reyes Natalia | F35: 23422070060 063 | G35: N/A | H35: nataliaresendiz3@cecyteq.edu.mx | I35: 5T0-BIO-AM | J35: MATUTINO | K35: BIOTECNOLOGÍA | L35: CONCLUIDO | M35: EMPRESA | N35: FORAPLAST S.A. DE C.V. | O35: MEDIANAS EMPRESAS | P35: x | Q35: 4421425696 | R35: FRANCISCO VILLA #1535 COL. LAS AMERICAS | S35: COMPRAS@FORAPLAST.COM | T35: 23-26 | U35: HOMBRE | V35: 1 | W35: N/A | X35: SI | Y35: 2 | Z35: 45911 | AA35: =DAY(Tabla1[F. INICIO]) -> 11 | AB35: =TEXT(' En tramite 23-26'!$Z35,"mmmm") -> septiembre | AC35: =YEAR(' En tramite 23-26'!$Z35) -> 2025 | AD35: SI | AE35: 2 | AF35: 45958 | AG35: SI | AH35: 2 | AI35: 45958 | AJ35: =DAY(' En tramite 23-26'!$AI35) -> 28 | AK35: =TEXT(' En tramite 23-26'!$AI35,"mmmm") -> octubre | AL35: =YEAR(' En tramite 23-26'!$Z35) -> 2025 | AM35: SI | AN35: 2 | AO35: 45958 | AP35: SI | AQ35: 2 | AR35: 46006 | AS35: =' En tramite 23-26'!$AI35+45 -> 46003 | AT35: ENTREGADO | AU35: SI | AV35: 2 | AW35: =' En tramite 23-26'!$AS35+45 -> 46048 | AX35: ENTREGADO | AY35: SI | AZ35: 2 | BA35: 46048 | BB35: SI | BC35: 2 | BD35: 46048 | BE35: =DAY(' En tramite 23-26'!$BD35) -> 26 | BF35: =TEXT(' En tramite 23-26'!$BD35,"mmmm") -> enero | BG35: =YEAR(' En tramite 23-26'!$BD35) -> 2026 | BH35: 1 | BI35: 2 meses 29 días | BJ35: BLOQUE 1 | BK35: P.P.E.C-BLOQUE 1 | BL35: 46213 | BM35: 2
A36: 033 | B36: 028 | C36: PC06/MATUTINO/028/2026 | D36: PÉREZ VARGAS MARÍA FERNANDA | E36: Pérez Vargas María Fernanda | F36: 23422070060 135 | G36: 4424539493 | H36: mariaperez2@cecyteq.edu.mx | I36: 5T0-LOG-AM | J36: MATUTINO | K36: LOGÍSTICA | L36: CONCLUIDO | M36: EMPRESA | N36: VICTORIO CHÁVEZ GIRÓN | O36: PEQUEÑAS EMPRESAS | P36: x | Q36: 4422240626 | R36: AV. CIMATARIO NO. 206 COL. LAS PALMAS | S36: sellosgiron@hotmail.com | T36: 23-26 | U36: MUJER | V36: 2 | W36: 1200 | X36: CORREGIR | Y36: 2 | Z36: 45965 | AA36: =DAY(Tabla1[F. INICIO]) -> 4 | AB36: =TEXT(' En tramite 23-26'!$Z36,"mmmm") -> noviembre | AC36: =YEAR(' En tramite 23-26'!$Z36) -> 2025 | AD36: SI | AE36: 2 | AF36: 45965 | AG36: SI | AH36: 2 | AI36: 45964 | AJ36: =DAY(' En tramite 23-26'!$AI36) -> 3 | AK36: =TEXT(' En tramite 23-26'!$AI36,"mmmm") -> noviembre | AL36: =YEAR(' En tramite 23-26'!$Z36) -> 2025 | AM36: SI | AN36: 2 | AO36: 45964 | AP36: SI | AQ36: 2 | AR36: 46034 | AS36: =' En tramite 23-26'!$AI36+45 -> 46009 | AT36: ENTREGADO | AU36: SI | AV36: 2 | AW36: 46079 | AX36: ENTREGADO | AY36: SI | AZ36: 2 | BA36: 46101 | BB36: SI | BC36: 2 | BD36: 46079 | BE36: =DAY(' En tramite 23-26'!$BD36) -> 26 | BF36: =TEXT(' En tramite 23-26'!$BD36,"mmmm") -> febrero | BG36: =YEAR(' En tramite 23-26'!$BD36) -> 2026 | BH36: 1 | BI36: 3 meses 23 días | BJ36: BLOQUE 1 | BK36: P.P.E.C-BLOQUE 1 | BL36: 46211 | BM36: 2
A37: 034 | B37: 029 | C37: PC06/MATUTINO/029/2026 | D37: RODRIGUEZ ARREOLA MIGUEL | E37: Rodriguez Arreola Miguel | F37: 23422070060 139 | G37: 4426072565 | H37: migelrodriguez196@cecyteq.edu.mx | I37: 5T0-LOG-AM | J37: MATUTINO | K37: LOGÍSTICA | L37: CONCLUIDO | M37: EMPRESA | N37: VICTORIO CHÁVEZ GIRÓN | O37: PEQUEÑAS EMPRESAS | P37: x | Q37: 4422240626 | R37: AV. CIMATARIO NO. 206 COL. LAS PALMAS | S37: sellosgiron@hotmail.com | T37: 23-26 | U37: HOMBRE | V37: 2 | W37: 1200 | X37: CORREGIR | Y37: 2 | Z37: 45965 | AA37: =DAY(Tabla1[F. INICIO]) -> 4 | AB37: =TEXT(' En tramite 23-26'!$Z37,"mmmm") -> noviembre | AC37: =YEAR(' En tramite 23-26'!$Z37) -> 2025 | AD37: SI | AE37: 2 | AF37: 45965 | AG37: SI | AH37: 2 | AI37: 45964 | AJ37: =DAY(' En tramite 23-26'!$AI37) -> 3 | AK37: =TEXT(' En tramite 23-26'!$AI37,"mmmm") -> noviembre | AL37: =YEAR(' En tramite 23-26'!$Z37) -> 2025 | AM37: SI | AN37: 2 | AO37: 45964 | AP37: SI | AQ37: 2 | AR37: 46034 | AS37: =' En tramite 23-26'!$AI37+45 -> 46009 | AT37: ENTREGADO | AU37: SI | AV37: 2 | AW37: 46079 | AX37: ENTREGADO | AY37: SI | AZ37: 2 | BA37: 46079 | BB37: SI | BC37: 2 | BD37: 46079 | BE37: =DAY(' En tramite 23-26'!$BD37) -> 26 | BF37: =TEXT(' En tramite 23-26'!$BD37,"mmmm") -> febrero | BG37: =YEAR(' En tramite 23-26'!$BD37) -> 2026 | BH37: 1 | BI37: 3 meses 23 día | BJ37: BLOQUE 1 | BK37: P.P.E.C-BLOQUE 1 | BL37: 46211 | BM37: 2
A38: 035 | B38: 030 | C38: PC06/MATUTINO/030/2026 | D38: CARRILLO RAMOS HANNA VANESSA | E38: Carrillo Ramos Hanna Vanessa | F38: 23422070060 332 | G38: 4421865631 | H38: hannacarrillo@cecyteq.edu.com | I38: 5T0-MECA-BM | J38: MATUTINO | K38: MECATRÓNICA | L38: CONCLUIDO | M38: EMPRESA | N38: EFICIENCIA EN FRIO AIRE ACONDICIONADO Y REFRIGERACIÓN | O38: PEQUEÑAS EMPRESAS | P38: x | Q38: 4422792072 | R38: AMATISTA NO.79 COL.DIAMANTE | S38: ontelmo.rdz@hotmail.com | T38: 23-26 | U38: MUJER | V38: 1 | W38: N/A | X38: SI | Y38: 2 | Z38: 45964 | AA38: =DAY(Tabla1[F. INICIO]) -> 3 | AB38: =TEXT(' En tramite 23-26'!$Z38,"mmmm") -> noviembre | AC38: =YEAR(' En tramite 23-26'!$Z38) -> 2025 | AD38: SI | AE38: 2 | AF38: 45964 | AG38: SI | AH38: 2 | AI38: 45973 | AJ38: =DAY(' En tramite 23-26'!$AI38) -> 12 | AK38: =TEXT(' En tramite 23-26'!$AI38,"mmmm") -> noviembre | AL38: =YEAR(' En tramite 23-26'!$Z38) -> 2025 | AM38: SI | AN38: 2 | AO38: 12/11/202 | AP38: SI | AQ38: 2 | AR38: 46355 | AS38: =' En tramite 23-26'!$AI38+45 -> 46018 | AT38: ENTREGADO | AU38: SI | AV38: 2 | AW38: 46062 | AX38: ENTREGADO | AY38: SI | AZ38: 2 | BA38: 46062 | BB38: SI | BC38: 2 | BD38: 46062 | BE38: =DAY(' En tramite 23-26'!$BD38) -> 9 | BF38: =TEXT(' En tramite 23-26'!$BD38,"mmmm") -> febrero | BG38: =YEAR(' En tramite 23-26'!$BD38) -> 2026 | BH38: 1 | BI38: 2 meses y 28 días. | BJ38: BLOQUE 1 | BK38: P.P.E.C-BLOQUE 1 | BL38: 46213 | BM38: 2
A39: 036 | B39: 031 | C39: PC06/MATUTINO/031/2026 | D39: VALENCIA GARCÍA LUCIANO GAEL | E39: Valencia García Luciano Gael | F39: 23422070060 273 | G39: 8120263431 | H39: lucianovalencia@cecyteq.edu.mx | I39: 5T0-MECA-BM | J39: MATUTINO | K39: MECATRÓNICA | L39: CONCLUIDO | M39: EMPRESA | N39: EFICIENCIA EN FRIO AIRE ACONDICIONADO Y REFRIGERACIÓN | O39: PEQUEÑAS EMPRESAS | P39: x | Q39: 4422792072 | R39: AMATISTA NO.79 COL.DIAMANTE | S39: ontelmo.rdz@hotmail.com | T39: 23-26 | U39: HOMBRE | V39: 1 | W39: N/A | X39: SI | Y39: 2 | Z39: 45964 | AA39: =DAY(Tabla1[F. INICIO]) -> 3 | AB39: =TEXT(' En tramite 23-26'!$Z39,"mmmm") -> noviembre | AC39: =YEAR(' En tramite 23-26'!$Z39) -> 2025 | AD39: SI | AE39: 2 | AF39: 45964 | AG39: SI | AH39: 2 | AI39: 45973 | AJ39: =DAY(' En tramite 23-26'!$AI39) -> 12 | AK39: =TEXT(' En tramite 23-26'!$AI39,"mmmm") -> noviembre | AL39: =YEAR(' En tramite 23-26'!$Z39) -> 2025 | AM39: SI | AN39: 2 | AO39: 12/11/202 | AP39: SI | AQ39: 2 | AR39: 46355 | AS39: =' En tramite 23-26'!$AI39+45 -> 46018 | AT39: ENTREGADO | AU39: SI | AV39: 2 | AW39: 46062 | AX39: ENTREGADO | AY39: SI | AZ39: 2 | BA39: 46062 | BB39: SI | BC39: 2 | BD39: 46062 | BE39: =DAY(' En tramite 23-26'!$BD39) -> 9 | BF39: =TEXT(' En tramite 23-26'!$BD39,"mmmm") -> febrero | BG39: =YEAR(' En tramite 23-26'!$BD39) -> 2026 | BH39: 1 | BI39: 2 meses y 28 días. | BJ39: BLOQUE 1 | BK39: P.P.E.C-BLOQUE 1 | BL39: 46213 | BM39: 2
A40: 037 | B40: 032 | C40: PC06/MATUTINO/032/2026 | D40: SÁNCHEZ MUÑOZ NÉSTOR YAHEL | E40: Sánchez Muñoz Néstor Yahel | F40: 23422070060 223 | G40: 4424238963 | H40: nestorsanchez12@cecyteq.edu.mx | I40: 5T0-MECA-AMBI | J40: MATUTINO | K40: MECATRÓNICA | L40: CONCLUIDO | M40: CERTIFICACIÓN | N40: CERTIFICACIONES SOLIDWORKS | O40: SECTOR PÚBLICO | P40: CERTIFICACIÓN | Q40: 4423622063 | R40: AV. CANDILES 317., VALLE REAL RECIDENCIAL C.P.76903 CANDILES QRO. | S40: e.armendariz@cecyteq.edu.mx | T40: 23-26 | U40: HOMBRE | V40: 1 | W40: N/A | X40: SI | Y40: 2 | Z40: 45985 | AA40: =DAY(Tabla1[F. INICIO]) -> 24 | AB40: =TEXT(' En tramite 23-26'!$Z40,"mmmm") -> noviembre | AC40: =YEAR(' En tramite 23-26'!$Z40) -> 2025 | AD40: SI | AE40: 2 | AF40: 45985 | AG40: SI | AH40: 2 | AI40: 45992 | AJ40: =DAY(' En tramite 23-26'!$AI40) -> 1 | AK40: =TEXT(' En tramite 23-26'!$AI40,"mmmm") -> diciembre | AL40: =YEAR(' En tramite 23-26'!$Z40) -> 2025 | AM40: SI | AN40: 2 | AO40: 45992 | AP40: SI | AQ40: 2 | AR40: 46037 | AS40: =' En tramite 23-26'!$AI40+45 -> 46037 | AT40: ENTREGADO | AU40: SI | AV40: 2 | AW40: 46099 | AX40: ENTREGADO | AY40: SI | AZ40: 2 | BA40: 46099 | BB40: SI | BC40: 2 | BD40: 46099 | BE40: =DAY(' En tramite 23-26'!$BD40) -> 18 | BF40: =TEXT(' En tramite 23-26'!$BD40,"mmmm") -> marzo | BG40: =YEAR(' En tramite 23-26'!$BD40) -> 2026 | BH40: 1 | BI40: 3 meses y 22 días. | BJ40: BLOQUE 1 | BK40: P.P.E.C-BLOQUE 1 | BL40: 46238 | BM40: 2
A41: 038 | B41: 033 | C41: PC06/MATUTINO/033/2026 | D41: RODRÍGUEZ FLORES EFRAIN ASAHEL | E41: Rodríguez Flores Efrain Asahel | F41: 23422070060 263 | G41: 4421812232 | H41: efrainrodriguez7@cecyteq.edu.mx | I41: 5T0-MECA-AMBI | J41: MATUTINO | K41: MECATRÓNICA | L41: CONCLUIDO | M41: CERTIFICACIÓN | N41: CERTIFICACIONES SOLIDWORKS | O41: SECTOR PÚBLICO | P41: CERTIFICACIÓN | Q41: 4423622063 | R41: AV. CANDILES 317., VALLE REAL RECIDENCIAL C.P.76903 CANDILES QRO. | S41: e.armendariz@cecyteq.edu.mx | T41: 23-26 | U41: HOMBRE | V41: 1 | W41: N/A | X41: SI | Y41: 2 | Z41: 45985 | AA41: =DAY(Tabla1[F. INICIO]) -> 24 | AB41: =TEXT(' En tramite 23-26'!$Z41,"mmmm") -> noviembre | AC41: =YEAR(' En tramite 23-26'!$Z41) -> 2025 | AD41: SI | AE41: 2 | AF41: 45985 | AG41: SI | AH41: 2 | AI41: 45985 | AJ41: =DAY(' En tramite 23-26'!$AI41) -> 24 | AK41: =TEXT(' En tramite 23-26'!$AI41,"mmmm") -> noviembre | AL41: =YEAR(' En tramite 23-26'!$Z41) -> 2025 | AM41: SI | AN41: 2 | AO41: 45986 | AP41: SI | AQ41: 2 | AR41: 46071 | AS41: =' En tramite 23-26'!$AI41+45 -> 46030 | AT41: ENTREGADO | AU41: SI | AV41: 2 | AW41: 46105 | AX41: ENTREGADO | AY41: SI | AZ41: 2 | BA41: 46105 | BB41: SI | BC41: 2 | BD41: 46105 | BE41: =DAY(' En tramite 23-26'!$BD41) -> 24 | BF41: =TEXT(' En tramite 23-26'!$BD41,"mmmm") -> marzo | BG41: =YEAR(' En tramite 23-26'!$BD41) -> 2026 | BH41: 1 | BI41: 4 meses | BJ41: BLOQUE 1 | BK41: P.P.E.C-BLOQUE 1 | BL41: 46211 | BM41: 2
...
